2023-02-21 16:08:01,763 DEBUG    root            Loaded Command Group: ['gcloud', 'auth']
2023-02-21 16:08:01,764 DEBUG    root            Loaded Command Group: ['gcloud', 'auth', 'login']
2023-02-21 16:08:01,766 DEBUG    root            Running [gcloud.auth.login] with arguments: [--cred-file: "=", ACCOUNT: "/Users/brad/neptune-337921-947c5b201e4c.json"]
2023-02-21 16:08:01,766 DEBUG    root            (gcloud.auth.login) Failed to load YAML from [=]: Unable to read file [=]: [Errno 2] No such file or directory: '='
Traceback (most recent call last):
  File "/Users/brad/google-cloud-sdk/lib/googlecloudsdk/core/util/files.py", line 1299, in _FileOpener
    return io.open(path, mode, encoding=encoding, newline=newline)
FileNotFoundError: [Errno 2] No such file or directory: '='

During handling of the above exception, another exception occurred:

Traceback (most recent call last):
  File "/Users/brad/google-cloud-sdk/lib/googlecloudsdk/core/yaml.py", line 190, in load_path
    with files.FileReader(path) as fp:
  File "/Users/brad/google-cloud-sdk/lib/googlecloudsdk/core/util/files.py", line 1200, in FileReader
    return _FileOpener(path, 'rt', 'read', encoding='utf-8')
  File "/Users/brad/google-cloud-sdk/lib/googlecloudsdk/core/util/files.py", line 1306, in _FileOpener
    raise exc_type('Unable to {0} file [{1}]: {2}'.format(verb, path, e))
googlecloudsdk.core.util.files.MissingFileError: Unable to read file [=]: [Errno 2] No such file or directory: '='

During handling of the above exception, another exception occurred:

Traceback (most recent call last):
  File "/Users/brad/google-cloud-sdk/lib/googlecloudsdk/calliope/cli.py", line 987, in Execute
    resources = calliope_command.Run(cli=self, args=args)
  File "/Users/brad/google-cloud-sdk/lib/googlecloudsdk/calliope/backend.py", line 807, in Run
    resources = command_instance.Run(args)
  File "/Users/brad/google-cloud-sdk/lib/surface/auth/login.py", line 237, in Run
    cred_file = auth_util.GetCredentialsConfigFromFile(args.cred_file)
  File "/Users/brad/google-cloud-sdk/lib/googlecloudsdk/api_lib/auth/util.py", line 97, in GetCredentialsConfigFromFile
    content = yaml.load_path(filename)
  File "/Users/brad/google-cloud-sdk/lib/googlecloudsdk/core/yaml.py", line 198, in load_path
    raise FileLoadError(e, f=path)
googlecloudsdk.core.yaml.FileLoadError: Failed to load YAML from [=]: Unable to read file [=]: [Errno 2] No such file or directory: '='
2023-02-21 16:08:01,767 ERROR    root            (gcloud.auth.login) Failed to load YAML from [=]: Unable to read file [=]: [Errno 2] No such file or directory: '='
2023-02-21 16:08:01,774 DEBUG    root            Metrics reporting process started...
